<?xml version="1.0" ?>
<!-- =================================================================================== -->
<!-- |    This document was autogenerated by xacro from /home/deck/dev_ws/install/cy-borg/share/cy-borg/description/cy-borg.urdf.xacro | -->
<!-- |    EDITING THIS FILE BY HAND IS NOT RECOMMENDED                                 | -->
<!-- =================================================================================== -->
<robot name="cy-borg">
  <!-- Specify some standard inertial calculations https://en.wikipedia.org/wiki/List_of_moments_of_inertia -->
  <!-- These make use of xacro's mathematical functionality -->
  <material name="white">
    <color rgba="1 1 1 1"/>
  </material>
  <material name="orange">
    <color rgba="1 0.3 0.1 1"/>
  </material>
  <material name="blue">
    <color rgba="0.2 0.2 1 1"/>
  </material>
  <material name="black">
    <color rgba="0 0 0 1"/>
  </material>
  <!--BASE LINK-->
  <link name="base_link">
    <origin xyz="0 0 0.5"/>
  </link>
  <!--CHASSIS LINK-->
  <joint name="chassis_joint" type="fixed">
    <parent link="base_link"/>
    <child link="chassis"/>
    <origin xyz="-0.1 0 0"/>
  </joint>
  <link name="chassis">
    <visual>
      <origin xyz="0.09525 0 0.01625"/>
      <geometry>
        <box size=".1905 0.1025 0.0325"/>
      </geometry>
      <material name="white"/>
    </visual>
    <collision>
      <origin xyz="0.09525 0 0.01625"/>
      <geometry>
        <box size="0.1905 0.1025 0.0325"/>
      </geometry>
    </collision>
    <inertial>
      <origin rpy="0 0 0" xyz="0.09525 0 0.01625"/>
      <mass value="1.2"/>
      <inertia ixx="0.0011562499999999997" ixy="0.0" ixz="0.0" iyy="0.00373465" iyz="0.0" izz="0.0046796500000000005"/>
    </inertial>
  </link>
  <!--FRONT LEFT WHEEL LINK-->
  <joint name="front_left_wheel_joint" type="continuous">
    <parent link="base_link"/>
    <child link="wheel_FL"/>
    <origin rpy="-1.5707963267948966 0 0" xyz="0.075 0.057 0.001"/>
    <axis xyz="0 0 1"/>
  </joint>
  <link name="wheel_FL">
    <visual>
      <geometry>
        <cylinder length="0.008" radius="0.0205"/>
      </geometry>
      <material name="orange"/>
    </visual>
    <collision>
      <geometry>
        <cylinder length="0.008" radius="0.0205"/>
      </geometry>
    </collision>
    <inertial>
      <origin rpy="0 0 0" xyz="0 0 0"/>
      <mass value="0.023"/>
      <inertia ixx="2.5391041666666666e-06" ixy="0.0" ixz="0.0" iyy="2.5391041666666666e-06" iyz="0.0" izz="4.832875000000001e-06"/>
    </inertial>
  </link>
  <!--FRONT RIGHT WHEEL LINK-->
  <joint name="front_right_wheel_joint" type="continuous">
    <parent link="base_link"/>
    <child link="wheel_FR"/>
    <origin rpy="1.5707963267948966 0 0" xyz="0.075 -0.057 0.001"/>
    <axis xyz="0 0 -1"/>
  </joint>
  <link name="wheel_FR">
    <visual>
      <geometry>
        <cylinder length="0.008" radius="0.0205"/>
      </geometry>
      <material name="orange"/>
    </visual>
    <collision>
      <geometry>
        <cylinder length="0.008" radius="0.0205"/>
      </geometry>
    </collision>
    <inertial>
      <origin rpy="0 0 0" xyz="0 0 0"/>
      <mass value="0.023"/>
      <inertia ixx="2.5391041666666666e-06" ixy="0.0" ixz="0.0" iyy="2.5391041666666666e-06" iyz="0.0" izz="4.832875000000001e-06"/>
    </inertial>
  </link>
  <!--BACK LEFT WHEEL LINK-->
  <joint name="back_left_wheel_joint" type="continuous">
    <parent link="base_link"/>
    <child link="wheel_BL"/>
    <origin rpy="-1.5707963267948966 0 0" xyz="-0.085 0.057 0.001"/>
    <axis xyz="0 0 1"/>
  </joint>
  <link name="wheel_BL">
    <visual>
      <geometry>
        <cylinder length="0.008" radius="0.0205"/>
      </geometry>
      <material name="orange"/>
    </visual>
    <collision>
      <geometry>
        <cylinder length="0.008" radius="0.0205"/>
      </geometry>
    </collision>
    <inertial>
      <origin rpy="0 0 0" xyz="0 0 0"/>
      <mass value="0.023"/>
      <inertia ixx="2.5391041666666666e-06" ixy="0.0" ixz="0.0" iyy="2.5391041666666666e-06" iyz="0.0" izz="4.832875000000001e-06"/>
    </inertial>
  </link>
  <!--BACK RIGHT WHEEL LINK-->
  <joint name="back_right_wheel_joint" type="continuous">
    <parent link="base_link"/>
    <child link="wheel_BR"/>
    <origin rpy="1.5707963267948966 0 0" xyz="-0.085 -0.057 0.001"/>
    <axis xyz="0 0 -1"/>
  </joint>
  <link name="wheel_BR">
    <visual>
      <geometry>
        <cylinder length="0.008" radius="0.0205"/>
      </geometry>
      <material name="orange"/>
    </visual>
    <collision>
      <geometry>
        <cylinder length="0.008" radius="0.0205"/>
      </geometry>
    </collision>
    <inertial>
      <origin rpy="0 0 0" xyz="0 0 0"/>
      <mass value="0.023"/>
      <inertia ixx="2.5391041666666666e-06" ixy="0.0" ixz="0.0" iyy="2.5391041666666666e-06" iyz="0.0" izz="4.832875000000001e-06"/>
    </inertial>
  </link>
  <!--<xacro:include filename="gazebo_control.xacro" />-->
  <!-- Robot description -->
  <ros2_control name="GazeboSimSystem" type="system">
    <hardware>
      <plugin>gz_ros2_control/GazeboSimSystem</plugin>
    </hardware>
    <joint name="front_left_wheel_joint">
      <command_interface name="velocity">
        <param name="min">-10</param>
        <param name="max">10</param>
      </command_interface>
      <state_interface name="position"/>
      <state_interface name="velocity"/>
    </joint>
    <joint name="back_left_wheel_joint">
      <command_interface name="velocity">
        <param name="min">-10</param>
        <param name="max">10</param>
      </command_interface>
      <state_interface name="position"/>
      <state_interface name="velocity"/>
    </joint>
    <joint name="front_right_wheel_joint">
      <command_interface name="velocity">
        <param name="min">-10</param>
        <param name="max">10</param>
      </command_interface>
      <state_interface name="position"/>
      <state_interface name="velocity"/>
    </joint>
    <joint name="back_right_wheel_joint">
      <command_interface name="velocity">
        <param name="min">-10</param>
        <param name="max">10</param>
      </command_interface>
      <state_interface name="position"/>
      <state_interface name="velocity"/>
    </joint>
  </ros2_control>
  <gazebo>
    <plugin filename="/opt/ros/jazzy/lib/libgz_ros2_control-system.so" name="gz_ros2_control::GazeboSimROS2ControlPlugin">
      <robot_param>robot_description</robot_param>
      <robot_param_node>robot_state_publisher</robot_param_node>
      <controller_manager_prefix_node_name>controller_manager</controller_manager_prefix_node_name>
      <parameters>src/cy-borg/config/diff_drive_controller.yaml</parameters>
    </plugin>
  </gazebo>
</robot>
