<?xml version="1.0" ?>
<!-- =================================================================================== -->
<!-- |    This document was autogenerated by xacro from /home/deck/dev_ws/install/cy-borg/share/cy-borg/description/cy-borg.urdf.xacro | -->
<!-- |    EDITING THIS FILE BY HAND IS NOT RECOMMENDED                                 | -->
<!-- =================================================================================== -->
<robot name="cy-borg">
  <!-- Specify some standard inertial calculations https://en.wikipedia.org/wiki/List_of_moments_of_inertia -->
  <!-- These make use of xacro's mathematical functionality -->
  <material name="white">
    <color rgba="1 1 1 1"/>
  </material>
  <material name="orange">
    <color rgba="1 0.3 0.1 1"/>
  </material>
  <material name="blue">
    <color rgba="0.2 0.2 1 1"/>
  </material>
  <material name="black">
    <color rgba="0 0 0 1"/>
  </material>
  <!--BASE LINK-->
  <link name="base_link">
    <origin xyz="0 0 0.5"/>
  </link>
  <!--CHASSIS LINK-->
  <joint name="chassis_joint" type="fixed">
    <parent link="base_link"/>
    <child link="chassis"/>
    <origin xyz="-0.1 0 0"/>
  </joint>
  <link name="chassis">
    <visual>
      <origin xyz="0.09525 0 0.01625"/>
      <geometry>
        <box size=".1905 0.1025 0.0325"/>
      </geometry>
      <material name="white"/>
    </visual>
    <collision>
      <origin xyz="0.09525 0 0.01625"/>
      <geometry>
        <box size="0.1905 0.1025 0.0325"/>
      </geometry>
    </collision>
    <inertial>
      <origin rpy="0 0 0" xyz="0.09525 0 0.01625"/>
      <mass value="1.2"/>
      <inertia ixx="0.0011562499999999997" ixy="0.0" ixz="0.0" iyy="0.00373465" iyz="0.0" izz="0.0046796500000000005"/>
    </inertial>
  </link>
  <!--FRONT LEFT WHEEL LINK-->
  <joint name="front_left_wheel_joint" type="continuous">
    <parent link="base_link"/>
    <child link="wheel_FL"/>
    <origin rpy="-1.5707963267948966 0 0" xyz="0.075 0.057 0.001"/>
    <axis xyz="0 0 1"/>
  </joint>
  <link name="wheel_FL">
    <visual>
      <geometry>
        <cylinder length="0.008" radius="0.0205"/>
      </geometry>
      <material name="orange"/>
    </visual>
    <collision>
      <geometry>
        <cylinder length="0.008" radius="0.0205"/>
      </geometry>
    </collision>
    <inertial>
      <origin rpy="0 0 0" xyz="0 0 0"/>
      <mass value="0.023"/>
      <inertia ixx="2.5391041666666666e-06" ixy="0.0" ixz="0.0" iyy="2.5391041666666666e-06" iyz="0.0" izz="4.832875000000001e-06"/>
    </inertial>
  </link>
  <!--FRONT RIGHT WHEEL LINK-->
  <joint name="front_right_wheel_joint" type="continuous">
    <parent link="base_link"/>
    <child link="wheel_FR"/>
    <origin rpy="1.5707963267948966 0 0" xyz="0.075 -0.057 0.001"/>
    <axis xyz="0 0 -1"/>
  </joint>
  <link name="wheel_FR">
    <visual>
      <geometry>
        <cylinder length="0.008" radius="0.0205"/>
      </geometry>
      <material name="orange"/>
    </visual>
    <collision>
      <geometry>
        <cylinder length="0.008" radius="0.0205"/>
      </geometry>
    </collision>
    <inertial>
      <origin rpy="0 0 0" xyz="0 0 0"/>
      <mass value="0.023"/>
      <inertia ixx="2.5391041666666666e-06" ixy="0.0" ixz="0.0" iyy="2.5391041666666666e-06" iyz="0.0" izz="4.832875000000001e-06"/>
    </inertial>
  </link>
  <!--BACK LEFT WHEEL LINK-->
  <joint name="back_left_wheel_joint" type="continuous">
    <parent link="base_link"/>
    <child link="wheel_BL"/>
    <origin rpy="-1.5707963267948966 0 0" xyz="-0.085 0.057 0.001"/>
    <axis xyz="0 0 1"/>
  </joint>
  <link name="wheel_BL">
    <visual>
      <geometry>
        <cylinder length="0.008" radius="0.0205"/>
      </geometry>
      <material name="orange"/>
    </visual>
    <collision>
      <geometry>
        <cylinder length="0.008" radius="0.0205"/>
      </geometry>
    </collision>
    <inertial>
      <origin rpy="0 0 0" xyz="0 0 0"/>
      <mass value="0.023"/>
      <inertia ixx="2.5391041666666666e-06" ixy="0.0" ixz="0.0" iyy="2.5391041666666666e-06" iyz="0.0" izz="4.832875000000001e-06"/>
    </inertial>
  </link>
  <!--BACK RIGHT WHEEL LINK-->
  <joint name="back_right_wheel_joint" type="continuous">
    <parent link="base_link"/>
    <child link="wheel_BR"/>
    <origin rpy="1.5707963267948966 0 0" xyz="-0.085 -0.057 0.001"/>
    <axis xyz="0 0 -1"/>
  </joint>
  <link name="wheel_BR">
    <visual>
      <geometry>
        <cylinder length="0.008" radius="0.0205"/>
      </geometry>
      <material name="orange"/>
    </visual>
    <collision>
      <geometry>
        <cylinder length="0.008" radius="0.0205"/>
      </geometry>
    </collision>
    <inertial>
      <origin rpy="0 0 0" xyz="0 0 0"/>
      <mass value="0.023"/>
      <inertia ixx="2.5391041666666666e-06" ixy="0.0" ixz="0.0" iyy="2.5391041666666666e-06" iyz="0.0" izz="4.832875000000001e-06"/>
    </inertial>
  </link>
  <robot name="cy_borg">
    <!-- Your robot description -->
    <!-- Differential drive plugin -->
    <gazebo>
      <plugin filename="libgazebo_ros_diff_drive.so" name="differential_drive_controller">
        <left_joint>front_left_wheel_joint</left_joint>
        <left_joint>back_left_wheel_joint</left_joint>
        <right_joint>front_right_wheel_joint</right_joint>
        <right_joint>back_right_wheel_joint</right_joint>
        <wheel_separation>0.1025</wheel_separation>
        <wheel_radius>0.0205</wheel_radius>
        <max_wheel_torque>1.0</max_wheel_torque>
        <max_wheel_acceleration>2.0</max_wheel_acceleration>
        <commandTopic>cmd_vel</commandTopic>
        <odometryTopic>odom</odometryTopic>
        <odometry_frame>odom</odometry_frame>
        <odometrySource>world</odometrySource>
        <publishOdomTF>true</publishOdomTF>
        <publishTf>1</publishTf>
        <robot_base_frame>base_link</robot_base_frame>
        <publish_odom>true</publish_odom>
        <publish_odom_tf>true</publish_odom_tf>
        <publish_wheel_tf>true</publish_wheel_tf>
      </plugin>
    </gazebo>
  </robot>
</robot>
